<?xml version="1.0"?>


<robot name="m100">

<material name="blue">
  <color rgba="0 0 0.8 1"/>
</material>
<material name="white">
  <color rgba="1 1 1 1"/>
</material>


  <link name = "base_link">
    <visual>
      <origin xyz="0 0 0" rpy="1.57 0 0"/>
      <geometry>
       <mesh filename="package://matrice100/mesh/met.STL" scale="4 4 4"/>
<!--<cylinder radius="0.2" length="0.4"/>-->
      </geometry>
    </visual>
  </link>

<joint name="leg1" type="fixed">
<parent link="base_link"/>
<child link="leg1"/>
<origin xyz="0.43 -0.63 -0.39"/>
</joint>

  <link name = "leg1">
    <visual>
	<origin xyz="0 0 0" rpy="1.57 0 0"/>
      <geometry>
       <mesh filename="package://matrice100/mesh/leg1.STL" scale="4 4 4"/>
      </geometry>
	<material name="blue"/>
    </visual>
  </link>

<joint name="leg2" type="fixed">
<parent link="base_link"/>
<child link="leg2"/>
<origin xyz="0.43 -0.63 -0.39"/>
</joint>

  <link name = "leg2">
    <visual>
	<origin xyz="0 0 0" rpy="1.57 0 1.57"/>
      <geometry>
       <mesh filename="package://matrice100/mesh/leg1.STL" scale="4 4 4"/>
      </geometry>
	<material name="blue"/>
    </visual>
  </link>


<joint name="leg3" type="fixed">
<parent link="base_link"/>
<child link="leg3"/>
<origin xyz="0.43 -0.63 -0.39"/>
</joint>

  <link name = "leg3">
    <visual>
	<origin xyz="0 0 0" rpy="1.57 0 3.14 "/>
      <geometry>
       <mesh filename="package://matrice100/mesh/leg1.STL" scale="4 4 4"/>
      </geometry>
	<material name="blue"/>
    </visual>
  </link>

<joint name="leg4" type="fixed">
<parent link="base_link"/>
<child link="leg4"/>
<origin xyz="0.43 -0.63 -0.39"/>
</joint>

  <link name = "leg4">
    <visual>
	<origin xyz="0 0 0" rpy="1.57 0 -1.57 "/>
      <geometry>
       <mesh filename="package://matrice100/mesh/leg1.STL" scale="4 4 4"/>
      </geometry>
	<material name="blue"/>
    </visual>
  </link>

<joint name="prop1" type="continuous">
<parent link="leg1"/>
<child link="prop1"/>
<axis xyz ="0 0 1"/>
<origin xyz="0.92 -0.92 0.87"/>
</joint>

  <link name = "prop1">
    <visual>
	<origin xyz="0 0 0" rpy="0 0 0 "/>
      <geometry>
       <box size = "0.8 0.1 0.05"/>
      </geometry>
	<material name="white"/>
    </visual>
  </link>

<joint name="prop2" type="continuous">
<parent link="leg2"/>
<child link="prop2"/>
<axis xyz ="0 0 1"/>
<origin xyz="0.92 0.92 0.87"/>
</joint>

  <link name = "prop2">
    <visual>
	<origin xyz="0 0 0" rpy="0 0 0 "/>
      <geometry>
       <box size = "0.8 0.1 0.05"/>
      </geometry>
	<material name="white"/>
    </visual>
  </link>

<joint name="prop3" type="continuous">
<parent link="leg3"/>
<child link="prop3"/>
<axis xyz ="0 0 1"/>
<origin xyz="-0.92 0.92 0.87"/>
</joint>

  <link name = "prop3">
    <visual>
	<origin xyz="0 0 0" rpy="0 0 0 "/>
      <geometry>
       <box size = "0.8 0.1 0.05"/>
      </geometry>
	<material name="white"/>
    </visual>
  </link>

<joint name="prop4" type="continuous">
<parent link="leg4"/>
<child link="prop4"/>
<axis xyz ="0 0 1"/>
<origin xyz="-0.92 -0.92 0.87"/>
</joint>

  <link name = "prop4">
    <visual>
	<origin xyz="0 0 0" rpy="0 0 0 "/>
      <geometry>
       <box size = "0.8 0.1 0.05"/>
      </geometry>
	<material name="white"/>
    </visual>
  </link>


</robot>
